ERROR: Exception:
Traceback (most recent call last):
  File "/home/ubuntu/new_dir/Hamtech_Rasa/env/lib/python3.6/site-packages/pip/_internal/cli/base_command.py", line 180, in _main
    status = self.run(options, args)
  File "/home/ubuntu/new_dir/Hamtech_Rasa/env/lib/python3.6/site-packages/pip/_internal/cli/req_command.py", line 205, in wrapper
    return func(self, options, args)
  File "/home/ubuntu/new_dir/Hamtech_Rasa/env/lib/python3.6/site-packages/pip/_internal/commands/install.py", line 319, in run
    reqs, check_supported_wheels=not options.target_dir
  File "/home/ubuntu/new_dir/Hamtech_Rasa/env/lib/python3.6/site-packages/pip/_internal/resolution/resolvelib/resolver.py", line 128, in resolve
    requirements, max_rounds=try_to_avoid_resolution_too_deep
  File "/home/ubuntu/new_dir/Hamtech_Rasa/env/lib/python3.6/site-packages/pip/_vendor/resolvelib/resolvers.py", line 473, in resolve
    state = resolution.resolve(requirements, max_rounds=max_rounds)
  File "/home/ubuntu/new_dir/Hamtech_Rasa/env/lib/python3.6/site-packages/pip/_vendor/resolvelib/resolvers.py", line 367, in resolve
    failure_causes = self._attempt_to_pin_criterion(name)
  File "/home/ubuntu/new_dir/Hamtech_Rasa/env/lib/python3.6/site-packages/pip/_vendor/resolvelib/resolvers.py", line 213, in _attempt_to_pin_criterion
    criteria = self._get_criteria_to_update(candidate)
  File "/home/ubuntu/new_dir/Hamtech_Rasa/env/lib/python3.6/site-packages/pip/_vendor/resolvelib/resolvers.py", line 203, in _get_criteria_to_update
    name, crit = self._merge_into_criterion(r, parent=candidate)
  File "/home/ubuntu/new_dir/Hamtech_Rasa/env/lib/python3.6/site-packages/pip/_vendor/resolvelib/resolvers.py", line 172, in _merge_into_criterion
    if not criterion.candidates:
  File "/home/ubuntu/new_dir/Hamtech_Rasa/env/lib/python3.6/site-packages/pip/_vendor/resolvelib/structs.py", line 139, in __bool__
    return bool(self._sequence)
  File "/home/ubuntu/new_dir/Hamtech_Rasa/env/lib/python3.6/site-packages/pip/_internal/resolution/resolvelib/found_candidates.py", line 143, in __bool__
    return any(self)
  File "/home/ubuntu/new_dir/Hamtech_Rasa/env/lib/python3.6/site-packages/pip/_internal/resolution/resolvelib/found_candidates.py", line 129, in <genexpr>
    return (c for c in iterator if id(c) not in self._incompatible_ids)
  File "/home/ubuntu/new_dir/Hamtech_Rasa/env/lib/python3.6/site-packages/pip/_internal/resolution/resolvelib/found_candidates.py", line 33, in _iter_built
    candidate = func()
  File "/home/ubuntu/new_dir/Hamtech_Rasa/env/lib/python3.6/site-packages/pip/_internal/resolution/resolvelib/factory.py", line 205, in _make_candidate_from_link
    version=version,
  File "/home/ubuntu/new_dir/Hamtech_Rasa/env/lib/python3.6/site-packages/pip/_internal/resolution/resolvelib/candidates.py", line 312, in __init__
    version=version,
  File "/home/ubuntu/new_dir/Hamtech_Rasa/env/lib/python3.6/site-packages/pip/_internal/resolution/resolvelib/candidates.py", line 151, in __init__
    self.dist = self._prepare()
  File "/home/ubuntu/new_dir/Hamtech_Rasa/env/lib/python3.6/site-packages/pip/_internal/resolution/resolvelib/candidates.py", line 234, in _prepare
    dist = self._prepare_distribution()
  File "/home/ubuntu/new_dir/Hamtech_Rasa/env/lib/python3.6/site-packages/pip/_internal/resolution/resolvelib/candidates.py", line 318, in _prepare_distribution
    self._ireq, parallel_builds=True
  File "/home/ubuntu/new_dir/Hamtech_Rasa/env/lib/python3.6/site-packages/pip/_internal/operations/prepare.py", line 508, in prepare_linked_requirement
    return self._prepare_linked_requirement(req, parallel_builds)
  File "/home/ubuntu/new_dir/Hamtech_Rasa/env/lib/python3.6/site-packages/pip/_internal/operations/prepare.py", line 552, in _prepare_linked_requirement
    self.download_dir, hashes
  File "/home/ubuntu/new_dir/Hamtech_Rasa/env/lib/python3.6/site-packages/pip/_internal/operations/prepare.py", line 243, in unpack_url
    hashes=hashes,
  File "/home/ubuntu/new_dir/Hamtech_Rasa/env/lib/python3.6/site-packages/pip/_internal/operations/prepare.py", line 102, in get_http_url
    from_path, content_type = download(link, temp_dir.path)
  File "/home/ubuntu/new_dir/Hamtech_Rasa/env/lib/python3.6/site-packages/pip/_internal/network/download.py", line 157, in __call__
    for chunk in chunks:
  File "/home/ubuntu/new_dir/Hamtech_Rasa/env/lib/python3.6/site-packages/pip/_internal/cli/progress_bars.py", line 152, in iter
    for x in it:
  File "/home/ubuntu/new_dir/Hamtech_Rasa/env/lib/python3.6/site-packages/pip/_internal/network/utils.py", line 86, in response_chunks
    decode_content=False,
  File "/home/ubuntu/new_dir/Hamtech_Rasa/env/lib/python3.6/site-packages/pip/_vendor/urllib3/response.py", line 576, in stream
    data = self.read(amt=amt, decode_content=decode_content)
  File "/home/ubuntu/new_dir/Hamtech_Rasa/env/lib/python3.6/site-packages/pip/_vendor/urllib3/response.py", line 519, in read
    data = self._fp.read(amt) if not fp_closed else b""
  File "/home/ubuntu/new_dir/Hamtech_Rasa/env/lib/python3.6/site-packages/pip/_vendor/cachecontrol/filewrapper.py", line 65, in read
    self._close()
  File "/home/ubuntu/new_dir/Hamtech_Rasa/env/lib/python3.6/site-packages/pip/_vendor/cachecontrol/filewrapper.py", line 52, in _close
    self.__callback(self.__buf.getvalue())
  File "/home/ubuntu/new_dir/Hamtech_Rasa/env/lib/python3.6/site-packages/pip/_vendor/cachecontrol/controller.py", line 309, in cache_response
    cache_url, self.serializer.dumps(request, response, body=body)
  File "/home/ubuntu/new_dir/Hamtech_Rasa/env/lib/python3.6/site-packages/pip/_vendor/cachecontrol/serialize.py", line 72, in dumps
    return b",".join([b"cc=4", msgpack.dumps(data, use_bin_type=True)])
  File "/home/ubuntu/new_dir/Hamtech_Rasa/env/lib/python3.6/site-packages/pip/_vendor/msgpack/__init__.py", line 35, in packb
    return Packer(**kwargs).pack(o)
  File "/home/ubuntu/new_dir/Hamtech_Rasa/env/lib/python3.6/site-packages/pip/_vendor/msgpack/fallback.py", line 960, in pack
    self._pack(obj)
  File "/home/ubuntu/new_dir/Hamtech_Rasa/env/lib/python3.6/site-packages/pip/_vendor/msgpack/fallback.py", line 944, in _pack
    len(obj), dict_iteritems(obj), nest_limit - 1
  File "/home/ubuntu/new_dir/Hamtech_Rasa/env/lib/python3.6/site-packages/pip/_vendor/msgpack/fallback.py", line 1045, in _pack_map_pairs
    self._pack(v, nest_limit - 1)
  File "/home/ubuntu/new_dir/Hamtech_Rasa/env/lib/python3.6/site-packages/pip/_vendor/msgpack/fallback.py", line 944, in _pack
    len(obj), dict_iteritems(obj), nest_limit - 1
  File "/home/ubuntu/new_dir/Hamtech_Rasa/env/lib/python3.6/site-packages/pip/_vendor/msgpack/fallback.py", line 1044, in _pack_map_pairs
    self._pack(k, nest_limit - 1)
  File "/home/ubuntu/new_dir/Hamtech_Rasa/env/lib/python3.6/site-packages/pip/_vendor/msgpack/fallback.py", line 896, in _pack
    return self._buffer.write(obj)
MemoryError
